Workbook

Sheet Read me
A1: Investment Research Library: cost-benefit analysis
A2: Checks that each plan covers its own AI costs and that subscriptions cover every monthly expense, GST and income tax. All money in NZD unless marked US$.
A4: How to use it
A5: 1. Inputs: check every blue number. Yellow cells are the assumptions that matter most; replace them with your real figures as soon as you have them.
A6: 2. Plans: the profit on one subscriber for each plan, at typical use and if they use every question.
A7: 3. Scenarios: change the number of subscribers to see monthly profit, GST to pay, income tax, and how many subscribers you need to break even.
A8: 4. After launch, replace the estimated cost per question with your real one: OpenAI dashboard cost for the month divided by questions answered.
A10: Colour legend
A11: Blue text = an input you can change. Black = a formula. Green = taken from another sheet. Yellow fill = key assumption to replace with your own figure.
A13: Sources (prices checked 30 September 2026; they change, so re-check before relying on them)
A14: Stripe NZ card fees: 2.65% + NZ$0.30 domestic, 3.5% + NZ$0.30 international (+2% if currency conversion), excluding GST. xero.com/nz/pricing-plans/pricing-and-fees-for-stripe/ ; wise.com/nz/blog/stripe-fees-nz
A15: Stripe Billing (subscriptions) fee: entered as 0.7% of billing volume. Check your Stripe dashboard (Settings > Billing) and change if different.
... A24: Your own time is not counted unless you enter a salary under Fixed costs. This workbook is a planning tool, not tax or accounting advice.

Sheet Inputs
A1: Inputs
A2: Blue = change me. Yellow = key assumption to replace with your own figure.
A4: Currency and tax
A5: Item | B5: Value | C5: Unit | D5: Source or note
A6: NZ dollars per US dollar | B6: 1.72 | C6: NZD per USD | D6: Check today's rate. Most service bills below are in US dollars.
A7: GST rate | B7: 0.15 | C7: % | D7: New Zealand GST.
A8: GST registered? (1 = yes, 0 = no) | B8: 1 | C8: switch | D8: Plan prices include GST. If not registered (turnover under NZ$60,000), set to 0 and you keep the full price.
A9: Income tax rate on profit | B9: 0.28 | C9: % | D9: NZ company rate. Sole traders: use your marginal personal rate.
A11: Payments (Stripe)
A12: Item | B12: Value | C12: Unit | D12: Source or note
A13: Card fee, domestic | B13: 0.0265 | C13: % of charge | D13: Stripe NZ, excluding GST.
A14: Card fee, international | B14: 0.035 | C14: % of charge | D14: Plus currency conversion below if charged in a different currency.
A15: Currency conversion fee (international) | B15: 0.02 | C15: % of charge | D15: Applies when the card is in another currency.
A16: Share of subscribers paying with overseas cards | B16: 0.2 | C16: % | D16: Your estimate. Migrants and overseas users raise this.
A17: Fixed fee per charge | B17: 0.3 | C17: NZD | D17: Per monthly payment.
A18: Stripe Billing fee | B18: 0.007 | C18: % of charge | D18: Subscription billing fee. Check your Stripe account.
A19: GST charged on Stripe fees | B19: 0.15 | C19: % | D19: Stripe fees are quoted excluding GST; you can claim it back if GST registered.
A21: AI cost per question (OpenAI)
A22: Item | B22: Value | C22: Unit | D22: Source or note
A23: Input tokens per question | B23: 15000 | C23: tokens | D23: Estimate: system prompt, library passages and tool results over several model calls. Replace with measured figure.
A24: Output tokens per question | B24: 900 | C24: tokens | D24: Estimate: the answer plus tool calls.
A25: Price per 1M input tokens | B25: 0.15 | C25: US$ | D25: gpt-4o-mini.
A26: Price per 1M output tokens | B26: 0.6 | C26: US$ | D26: gpt-4o-mini.
A27: Embedding tokens per question | B27: 60 | C27: tokens | D27: The question is embedded once for library search.
A28: Price per 1M embedding tokens | B28: 0.02 | C28: US$ | D28: text-embedding-3-small.
A29: Buffer for retries and checked answers | B29: 0.25 | C29: % | D29: Extra calls when an answer is checked before showing, and failed attempts.
A30: Comparison: larger model, input per 1M | B30: 2.5 | C30: US$ | D30: gpt-4o, to see what switching models would do.
A31: Comparison: larger model, output per 1M | B31: 10 | C31: US$ | D31: gpt-4o.
A33: Database costs per question (Upstash)
A34: Item | B34: Value | C34: Unit | D34: Source or note
A35: Redis commands per question | B35: 6 | C35: commands | D35: Usage limits and checks.
A36: Redis price per 100K commands | B36: 0.2 | C36: US$ | D36: Pay as you go. Free tier (500K a month) ignored to stay on the safe side.
A37: Vector searches per question | B37: 1.5 | C37: requests | D37: Library searches.
A38: Vector price per 100K requests | B38: 0.4 | C38: US$ | D38: Pay as you go.
A40: Fixed monthly costs
A41: Item | B41: Value | C41: Unit | D41: Source or note
A42: Vercel Pro (hosting) | B42: 20 | C42: US$ / month | D42: Required for a paid product. 1 seat, includes US$20 usage credit.
A43: Clerk (sign-in) | B43: 0 | C43: US$ / month | D43: Free to 50,000 users. Set 25 for Pro (MFA, no Clerk branding).
A44: Upstash fixed plan (optional) | B44: 0 | C44: US$ / month | D44: Leave 0 on pay as you go.
A45: Domain name | B45: 3 | C45: NZD / month | D45: About NZ$35 a year. Your estimate.
...

Sheet Plans
A1: Profit on one subscriber, per month
A2: Typical use = the share of the allowance people usually use. Worst case = every question used.
B4: Free | C4: Basic | D4: Premium | E4: Adviser | F4: Note
A5: Price including GST | B5: 0 | C5: 15 | D5: 29 | E5: 150 | F5: From lib/plans.ts. Change here and in the app together.
A6: Questions a month | B6: 5 | C6: 150 | D6: 300 | E6: 1000 | F6: Monthly allowance.
A7: Typical share of allowance used | B7: =Inputs!$B$57 -> 0.6 | C7: 0.35 | D7: 0.3 | E7: 0.4 | F7: Your estimate. Free uses the Inputs figure.
A8: GST included in the price | B8: =B5-B5/(1+Inputs!$B$7*Inputs!$B$8) -> 0 | C8: =C5-C5/(1+Inputs!$B$7*Inputs!$B$8) -> 1.9565217 | D8: =D5-D5/(1+Inputs!$B$7*Inputs!$B$8) -> 3.7826087 | E8: =E5-E5/(1+Inputs!$B$7*Inputs!$B$8) -> 19.565217 | F8: Paid to IRD if GST registered.
A9: Price after GST | B9: =B5-B8 -> 0 | C9: =C5-C8 -> 13.043478 | D9: =D5-D8 -> 25.217391 | E9: =E5-E8 -> 130.43478
A10: Stripe fees (plus GST on fees if not registered) | B10: =IF(B5=0,0,(B5*Inputs!$B$67+Inputs!$B$17)*(1+Inputs!$B$19*(1-Inputs!$B$8))) -> 0 | C10: =IF(C5=0,0,(C5*Inputs!$B$67+Inputs!$B$17)*(1+Inputs!$B$19*(1-Inputs!$B$8))) -> 0.888 | D10: =IF(D5=0,0,(D5*Inputs!$B$67+Inputs!$B$17)*(1+Inputs!$B$19*(1-Inputs!$B$8))) -> 1.4368 | E10: =IF(E5=0,0,(E5*Inputs!$B$67+Inputs!$B$17)*(1+Inputs!$B$19*(1-Inputs!$B$8))) -> 6.18 | F10: GST on fees is claimed back when registered.
A11: Questions used, typical | B11: =B6*B7 -> 3 | C11: =C6*C7 -> 52.5 | D11: =D6*D7 -> 90 | E11: =E6*E7 -> 400
A12: Question costs, typical | B12: =B11*Inputs!$B$65 -> 0.01809612 | C12: =C11*Inputs!$B$65 -> 0.3166821 | D12: =D11*Inputs!$B$65 -> 0.5428836 | E12: =E11*Inputs!$B$65 -> 2.412816 | F12: AI and database costs.
A13: Profit per subscriber, typical | B13: =B9-B10-B12 -> -0.01809612 | C13: =C9-C10-C12 -> 11.838796 | D13: =D9-D10-D12 -> 23.237708 | E13: =E9-E10-E12 -> 121.84197 | F13: Before fixed costs and income tax.
A14: Margin, typical | B14: =IF(B9=0,0,B13/B9) -> 0 | C14: =IF(C9=0,0,C13/C9) -> 0.90764104 | D14: =IF(D9=0,0,D13/D9) -> 0.92149531 | E14: =IF(E9=0,0,E13/E9) -> 0.93412174
A15: Question costs, worst case | B15: =B6*Inputs!$B$65 -> 0.0301602 | C15: =C6*Inputs!$B$65 -> 0.904806 | D15: =D6*Inputs!$B$65 -> 1.809612 | E15: =E6*Inputs!$B$65 -> 6.03204 | F15: Every question in the allowance used.
A16: Profit per subscriber, worst case | B16: =B9-B10-B15 -> -0.0301602 | C16: =C9-C10-C15 -> 11.250672 | D16: =D9-D10-D15 -> 21.970979 | E16: =E9-E10-E15 -> 118.22274
A17: Question costs, worst case, larger model | B17: =B6*Inputs!$B$66 -> 0.5000427 | C17: =C6*Inputs!$B$66 -> 15.001281 | D17: =D6*Inputs!$B$66 -> 30.002562 | E17: =E6*Inputs!$B$66 -> 100.00854 | F17: If you switch to gpt-4o.
A18: Profit per subscriber, worst case, larger model | B18: =B9-B10-B17 -> -0.5000427 | C18: =C9-C10-C17 -> -2.8458027 | D18: =D9-D10-D17 -> -6.2219707 | E18: =E9-E10-E17 -> 24.246243 | F18: Negative means that plan would lose money on heavy users.
A19: Still profitable at worst case? | B19: =IF(B5=0,"Free plan",IF(B16>0,"Yes","No")) -> Free plan | C19: =IF(C5=0,"Free plan",IF(C16>0,"Yes","No")) -> Yes | D19: =IF(D5=0,"Free plan",IF(D16>0,"Yes","No")) -> Yes | E19: =IF(E5=0,"Free plan",IF(E16>0,"Yes","No")) -> Yes

Sheet Scenarios
A1: Monthly profit and loss
A2: Enter subscriber numbers in blue. Free accounts and visitors follow the ratios on the Inputs sheet.
B4: Launch | C4: Growing | D4: Established | E4: Note
A5: Basic subscribers | B5: 20 | C5: 100 | D5: 400
A6: Premium subscribers | B6: 10 | C6: 50 | D6: 200
A7: Adviser subscribers | B7: 0 | C7: 3 | D7: 15
A8: Paying subscribers | B8: =SUM(B5:B7) -> 30 | C8: =SUM(C5:C7) -> 153 | D8: =SUM(D5:D7) -> 615
A9: Free accounts | B9: =B8*Inputs!$B$58 -> 300 | C9: =C8*Inputs!$B$58 -> 1530 | D9: =D8*Inputs!$B$58 -> 6150 | E9: From Inputs ratio.
A10: Visitors asking without an account | B10: =B8*Inputs!$B$59 -> 600 | C10: =C8*Inputs!$B$59 -> 3060 | D10: =D8*Inputs!$B$59 -> 12300 | E10: From Inputs ratio.
A11: Revenue including GST | B11: =B5*Plans!$C$5+B6*Plans!$D$5+B7*Plans!$E$5 -> 590 | C11: =C5*Plans!$C$5+C6*Plans!$D$5+C7*Plans!$E$5 -> 3400 | D11: =D5*Plans!$C$5+D6*Plans!$D$5+D7*Plans!$E$5 -> 14050
A12: GST to pay IRD | B12: =B5*Plans!$C$8+B6*Plans!$D$8+B7*Plans!$E$8 -> 76.956522 | C12: =C5*Plans!$C$8+C6*Plans!$D$8+C7*Plans!$E$8 -> 443.47826 | D12: =D5*Plans!$C$8+D6*Plans!$D$8+D7*Plans!$E$8 -> 1832.6087 | E12: Set aside; not your money.
A13: Revenue after GST | B13: =B11-B12 -> 513.04348 | C13: =C11-C12 -> 2956.5217 | D13: =D11-D12 -> 12217.391
A14: Stripe fees | B14: =B5*Plans!$C$10+B6*Plans!$D$10+B7*Plans!$E$10 -> 32.128 | C14: =C5*Plans!$C$10+C6*Plans!$D$10+C7*Plans!$E$10 -> 179.18 | D14: =D5*Plans!$C$10+D6*Plans!$D$10+D7*Plans!$E$10 -> 735.26
A15: Question costs, paying subscribers | B15: =B5*Plans!$C$12+B6*Plans!$D$12+B7*Plans!$E$12 -> 11.762478 | C15: =C5*Plans!$C$12+C6*Plans!$D$12+C7*Plans!$E$12 -> 66.050838 | D15: =D5*Plans!$C$12+D6*Plans!$D$12+D7*Plans!$E$12 -> 271.4418 | E15: Typical use.
A16: Question costs, free accounts and visitors | B16: =(B9*Plans!$B$6+B10*2)*Inputs!$B$57*Inputs!$B$65 -> 9.7719048 | C16: =(C9*Plans!$B$6+C10*2)*Inputs!$B$57*Inputs!$B$65 -> 49.836714 | D16: =(D9*Plans!$B$6+D10*2)*Inputs!$B$57*Inputs!$B$65 -> 200.32405 | E16: Visitors: 2 questions a month.
A17: Fixed costs | B17: =Inputs!$B$68 -> 700.73333 | C17: =Inputs!$B$68 -> 700.73333 | D17: =Inputs!$B$68 -> 700.73333 | E17: Hosting, software, insurance, legal, marketing, your pay.
A18: Total costs | B18: =SUM(B14:B17) -> 754.39572 | C18: =SUM(C14:C17) -> 995.80089 | D18: =SUM(D14:D17) -> 1907.7592
A19: Profit before tax | B19: =B13-B18 -> -241.35224 | C19: =C13-C18 -> 1960.7209 | D19: =D13-D18 -> 10309.632
A20: Income tax | B20: =MAX(0,B19)*Inputs!$B$9 -> 0 | C20: =MAX(0,C19)*Inputs!$B$9 -> 549.00184 | D20: =MAX(0,D19)*Inputs!$B$9 -> 2886.697 | E20: Simplified: monthly share of the yearly tax bill.
A21: Profit after tax | B21: =B19-B20 -> -241.35224 | C21: =C19-C20 -> 1411.719 | D21: =D19-D20 -> 7422.9351
A22: Profit after tax, per year | B22: =B21*12 -> -2896.2269 | C22: =C21*12 -> 16940.628 | D22: =D21*12 -> 89075.222
A23: All costs and taxes covered? | B23: =IF(B21>=0,"Yes","Not yet") -> Not yet | C23: =IF(C21>=0,"Yes","Not yet") -> Yes | D23: =IF(D21>=0,"Yes","Not yet") -> Yes
A25: Break-even
A26: Average profit per paying subscriber (typical use) | B26: =IF(B8=0,0,(B5*Plans!$C$13+B6*Plans!$D$13+B7*Plans!$E$13)/B8) -> 15.638433 | C26: =IF(C8=0,0,(C5*Plans!$C$13+C6*Plans!$D$13+C7*Plans!$E$13)/C8) -> 17.720856 | D26: =IF(D8=0,0,(D5*Plans!$C$13+D6*Plans!$D$13+D7*Plans!$E$13)/D8) -> 18.228763 | E26: Uses this column's plan mix.
A27: Cost of free users per paying subscriber | B27: =(Inputs!$B$58*Plans!$B$6+Inputs!$B$59*2)*Inputs!$B$57*Inputs!$B$65 -> 0.32573016 | C27: =(Inputs!$B$58*Plans!$B$6+Inputs!$B$59*2)*Inputs!$B$57*Inputs!$B$65 -> 0.32573016 | D27: =(Inputs!$B$58*Plans!$B$6+Inputs!$B$59*2)*Inputs!$B$57*Inputs!$B$65 -> 0.32573016
A28: Paying subscribers needed to cover fixed costs | B28: =IF(B26-B27<=0,"Never",ROUNDUP(Inputs!$B$68/(B26-B27),0)) -> 46 | C28: =IF(C26-C27<=0,"Never",ROUNDUP(Inputs!$B$68/(C26-C27),0)) -> 41 | D28: =IF(D26-D27<=0,"Never",ROUNDUP(Inputs!$B$68/(D26-D27),0)) -> 40 | E28: At this column's plan mix.
